Exception in Tkinter callback
Traceback (most recent call last):
  File "/Users/runner/hostedtoolcache/Python/3.9.16/x64/lib/python3.9/tkinter/__init__.py", line 1892, in __call__
    return self.func(*args)
  File "/Users/runner/hostedtoolcache/Python/3.9.16/x64/lib/python3.9/tkinter/__init__.py", line 814, in callit
    func(*args)
  File "/Users/runner/hostedtoolcache/Python/3.9.16/x64/lib/python3.9/site-packages/matplotlib/backends/_backend_tk.py", line 271, in idle_draw
    self.draw()
  File "/Users/runner/hostedtoolcache/Python/3.9.16/x64/lib/python3.9/site-packages/matplotlib/backends/backend_tkagg.py", line 10, in draw
    super().draw()
  File "/Users/runner/hostedtoolcache/Python/3.9.16/x64/lib/python3.9/site-packages/matplotlib/backends/backend_agg.py", line 400, in draw
    self.figure.draw(self.renderer)
  File "/Users/runner/hostedtoolcache/Python/3.9.16/x64/lib/python3.9/site-packages/matplotlib/artist.py", line 95, in draw_wrapper
    result = draw(artist, renderer, *args, **kwargs)
  File "/Users/runner/hostedtoolcache/Python/3.9.16/x64/lib/python3.9/site-packages/matplotlib/artist.py", line 72, in draw_wrapper
    return draw(artist, renderer)
  File "/Users/runner/hostedtoolcache/Python/3.9.16/x64/lib/python3.9/site-packages/matplotlib/figure.py", line 3140, in draw
    mimage._draw_list_compositing_images(
  File "/Users/runner/hostedtoolcache/Python/3.9.16/x64/lib/python3.9/site-packages/matplotlib/image.py", line 131, in _draw_list_compositing_images
    a.draw(renderer)
  File "/Users/runner/hostedtoolcache/Python/3.9.16/x64/lib/python3.9/site-packages/matplotlib/artist.py", line 72, in draw_wrapper
    return draw(artist, renderer)
  File "/Users/runner/hostedtoolcache/Python/3.9.16/x64/lib/python3.9/site-packages/matplotlib/axes/_base.py", line 3028, in draw
    self._update_title_position(renderer)
  File "/Users/runner/hostedtoolcache/Python/3.9.16/x64/lib/python3.9/site-packages/matplotlib/axes/_base.py", line 2961, in _update_title_position
    if (ax.xaxis.get_ticks_position() in ['top', 'unknown']
  File "/Users/runner/hostedtoolcache/Python/3.9.16/x64/lib/python3.9/site-packages/matplotlib/axis.py", line 2451, in get_ticks_position
    self._get_ticks_position()]
  File "/Users/runner/hostedtoolcache/Python/3.9.16/x64/lib/python3.9/site-packages/matplotlib/axis.py", line 2156, in _get_ticks_position
    minor = self.minorTicks[0]
IndexError: list index out of range
