Exception in thread Thread-2:
Traceback (most recent call last):
  File "/Users/runner/hostedtoolcache/Python/3.9.10/x64/lib/python3.9/threading.py", line 973, in _bootstrap_inner
