Exception in Tkinter callback
Traceback (most recent call last):
  File "C:\hostedtoolcache\windows\Python\3.9.10\x64\lib\tkinter\__init__.py", line 1892, in __call__
    return self.func(*args)
  File "C:\hostedtoolcache\windows\Python\3.9.10\x64\lib\tkinter\__init__.py", line 814, in callit
    func(*args)
  File "C:\hostedtoolcache\windows\Python\3.9.10\x64\lib\site-packages\matplotlib\backends\_backend_tk.py", line 251, in idle_draw
    self.draw()
  File "C:\hostedtoolcache\windows\Python\3.9.10\x64\lib\site-packages\matplotlib\backends\backend_tkagg.py", line 9, in draw
    super().draw()
  File "C:\hostedtoolcache\windows\Python\3.9.10\x64\lib\site-packages\matplotlib\backends\backend_agg.py", line 436, in draw
    self.figure.draw(self.renderer)
  File "C:\hostedtoolcache\windows\Python\3.9.10\x64\lib\site-packages\matplotlib\artist.py", line 73, in draw_wrapper
    result = draw(artist, renderer, *args, **kwargs)
  File "C:\hostedtoolcache\windows\Python\3.9.10\x64\lib\site-packages\matplotlib\artist.py", line 50, in draw_wrapper
    return draw(artist, renderer)
  File "C:\hostedtoolcache\windows\Python\3.9.10\x64\lib\site-packages\matplotlib\figure.py", line 2810, in draw
    mimage._draw_list_compositing_images(
  File "C:\hostedtoolcache\windows\Python\3.9.10\x64\lib\site-packages\matplotlib\image.py", line 132, in _draw_list_compositing_images
    a.draw(renderer)
  File "C:\hostedtoolcache\windows\Python\3.9.10\x64\lib\site-packages\matplotlib\artist.py", line 50, in draw_wrapper
    return draw(artist, renderer)
  File "C:\hostedtoolcache\windows\Python\3.9.10\x64\lib\site-packages\matplotlib\axes\_base.py", line 3046, in draw
    self._update_title_position(renderer)
  File "C:\hostedtoolcache\windows\Python\3.9.10\x64\lib\site-packages\matplotlib\axes\_base.py", line 2984, in _update_title_position
    if (ax.xaxis.get_ticks_position() in ['top', 'unknown']
  File "C:\hostedtoolcache\windows\Python\3.9.10\x64\lib\site-packages\matplotlib\axis.py", line 2232, in get_ticks_position
    self._get_ticks_position()]
  File "C:\hostedtoolcache\windows\Python\3.9.10\x64\lib\site-packages\matplotlib\axis.py", line 1937, in _get_ticks_position
    minor = self.minorTicks[0]
IndexError: list index out of range
