Exception in Tkinter callback
Traceback (most recent call last):
  File "C:\hostedtoolcache\windows\Python\3.11.2\x64\Lib\tkinter\__init__.py", line 1948, in __call__
    return self.func(*args)
           ^^^^^^^^^^^^^^^^
  File "C:\hostedtoolcache\windows\Python\3.11.2\x64\Lib\tkinter\__init__.py", line 861, in callit
    func(*args)
  File "C:\hostedtoolcache\windows\Python\3.11.2\x64\Lib\site-packages\matplotlib\backends\_backend_tk.py", line 271, in idle_draw
    self.draw()
  File "C:\hostedtoolcache\windows\Python\3.11.2\x64\Lib\site-packages\matplotlib\backends\backend_tkagg.py", line 10, in draw
    super().draw()
  File "C:\hostedtoolcache\windows\Python\3.11.2\x64\Lib\site-packages\matplotlib\backends\backend_agg.py", line 400, in draw
    self.figure.draw(self.renderer)
  File "C:\hostedtoolcache\windows\Python\3.11.2\x64\Lib\site-packages\matplotlib\artist.py", line 95, in draw_wrapper
    result = draw(artist, renderer, *args, **kwargs)
             ^^^^^^^^^^^^^^^^^^^^^^^^^^^^^^^^^^^^^^^
  File "C:\hostedtoolcache\windows\Python\3.11.2\x64\Lib\site-packages\matplotlib\artist.py", line 72, in draw_wrapper
    return draw(artist, renderer)
           ^^^^^^^^^^^^^^^^^^^^^^
  File "C:\hostedtoolcache\windows\Python\3.11.2\x64\Lib\site-packages\matplotlib\figure.py", line 3134, in draw
    self.get_layout_engine().execute(self)
  File "C:\hostedtoolcache\windows\Python\3.11.2\x64\Lib\site-packages\matplotlib\layout_engine.py", line 178, in execute
    kwargs = get_tight_layout_figure(
             ^^^^^^^^^^^^^^^^^^^^^^^^
  File "C:\hostedtoolcache\windows\Python\3.11.2\x64\Lib\site-packages\matplotlib\_tight_layout.py", line 293, in get_tight_layout_figure
    kwargs = _auto_adjust_subplotpars(fig, renderer,
             ^^^^^^^^^^^^^^^^^^^^^^^^^^^^^^^^^^^^^^^
  File "C:\hostedtoolcache\windows\Python\3.11.2\x64\Lib\site-packages\matplotlib\_tight_layout.py", line 82, in _auto_adjust_subplotpars
    bb += [martist._get_tightbbox_for_layout_only(ax, renderer)]
           ^^^^^^^^^^^^^^^^^^^^^^^^^^^^^^^^^^^^^^^^^^^^^^^^^^^^
  File "C:\hostedtoolcache\windows\Python\3.11.2\x64\Lib\site-packages\matplotlib\artist.py", line 1415, in _get_tightbbox_for_layout_only
    return obj.get_tightbbox(*args, **{**kwargs, "for_layout_only": True})
           ^^^^^^^^^^^^^^^^^^^^^^^^^^^^^^^^^^^^^^^^^^^^^^^^^^^^^^^^^^^^^^^
  File "C:\hostedtoolcache\windows\Python\3.11.2\x64\Lib\site-packages\matplotlib\axes\_base.py", line 4388, in get_tightbbox
    self._update_title_position(renderer)
  File "C:\hostedtoolcache\windows\Python\3.11.2\x64\Lib\site-packages\matplotlib\axes\_base.py", line 2961, in _update_title_position
    if (ax.xaxis.get_ticks_position() in ['top', 'unknown']
        ^^^^^^^^^^^^^^^^^^^^^^^^^^^^^
  File "C:\hostedtoolcache\windows\Python\3.11.2\x64\Lib\site-packages\matplotlib\axis.py", line 2451, in get_ticks_position
    self._get_ticks_position()]
    ^^^^^^^^^^^^^^^^^^^^^^^^^^
  File "C:\hostedtoolcache\windows\Python\3.11.2\x64\Lib\site-packages\matplotlib\axis.py", line 2155, in _get_ticks_position
    major = self.majorTicks[0]
            ~~~~~~~~~~~~~~~^^^
IndexError: list index out of range
