Exception in Tkinter callback
Traceback (most recent call last):
  File "/Library/Frameworks/Python.framework/Versions/3.11/lib/python3.11/tkinter/__init__.py", line 1948, in __call__
    return self.func(*args)
           ^^^^^^^^^^^^^^^^
  File "/Users/runner/work/rfswarm/rfswarm/rfswarm_manager/rfswarm.py", line 5845, in sr_test_validate
    tol = self.scriptgrid.grid_slaves(column=self.plancoltst, row=r)[0]
          ~~~~~~~~~~~~~~~~~~~~~~~~~~~~~~~~~~~~~~~~~~~~~~~~~~~~~~~~~~^^^
IndexError: list index out of range
Exception in Tkinter callback
Traceback (most recent call last):
  File "/Library/Frameworks/Python.framework/Versions/3.11/lib/python3.11/tkinter/__init__.py", line 1948, in __call__
    return self.func(*args)
           ^^^^^^^^^^^^^^^^
  File "/Users/runner/work/rfswarm/rfswarm/rfswarm_manager/rfswarm.py", line 3330, in on_closing
    core.on_closing()
    ^^^^
NameError: name 'core' is not defined
Traceback (most recent call last):
  File "/Users/runner/work/rfswarm/rfswarm/rfswarm_manager/rfswarm.py", line 6992, in <module>
    core = RFSwarmCore()
           ^^^^^^^^^^^^^
  File "/Users/runner/work/rfswarm/rfswarm/rfswarm_manager/rfswarm.py", line 2263, in __init__
    self.BuildCore()
  File "/Users/runner/work/rfswarm/rfswarm/rfswarm_manager/rfswarm.py", line 2280, in BuildCore
    self.BuildCorePlan()
  File "/Users/runner/work/rfswarm/rfswarm/rfswarm_manager/rfswarm.py", line 2523, in BuildCorePlan
    base.addScriptRow()
  File "/Users/runner/work/rfswarm/rfswarm/rfswarm_manager/rfswarm.py", line 1700, in addScriptRow
    base.gui.addScriptRow()
  File "/Users/runner/work/rfswarm/rfswarm/rfswarm_manager/rfswarm.py", line 5581, in addScriptRow
    self.sg_canvas.config(scrollregion=self.sg_canvas.bbox("all"))
                                       ^^^^^^^^^^^^^^^^^^^^^^^^^^
  File "/Library/Frameworks/Python.framework/Versions/3.11/lib/python3.11/tkinter/__init__.py", line 2787, in bbox
    self.tk.call((self._w, 'bbox') + args)) or None
    ^^^^^^^^^^^^^^^^^^^^^^^^^^^^^^^^^^^^^^
_tkinter.TclError: invalid command name ".!rfswarmgui.!notebook.!frame.!frame2.!canvas"
Exception in thread Thread-7 (pln_update_graph):
Traceback (most recent call last):
  File "/Library/Frameworks/Python.framework/Versions/3.11/lib/python3.11/threading.py", line 1038, in _bootstrap_inner
    self.run()
  File "/Library/Frameworks/Python.framework/Versions/3.11/lib/python3.11/threading.py", line 975, in run
    self._target(*self._args, **self._kwargs)
  File "/Users/runner/work/rfswarm/rfswarm/rfswarm_manager/rfswarm.py", line 5488, in pln_update_graph
    self.canvas.draw()
  File "/Library/Frameworks/Python.framework/Versions/3.11/lib/python3.11/site-packages/matplotlib/backends/backend_tkagg.py", line 11, in draw
    self.blit()
  File "/Library/Frameworks/Python.framework/Versions/3.11/lib/python3.11/site-packages/matplotlib/backends/backend_tkagg.py", line 14, in blit
    _backend_tk.blit(self._tkphoto, self.renderer.buffer_rgba(),
  File "/Library/Frameworks/Python.framework/Versions/3.11/lib/python3.11/site-packages/matplotlib/backends/_backend_tk.py", line 116, in blit
    photoimage.tk.call(_blit_tcl_name, argsid)
RuntimeError: main thread is not in main loop
Exception ignored in: <function Variable.__del__ at 0x1037013a0>
Traceback (most recent call last):
  File "/Library/Frameworks/Python.framework/Versions/3.11/lib/python3.11/tkinter/__init__.py", line 410, in __del__
    if self._tk.getboolean(self._tk.call("info", "exists", self._name)):
                           ^^^^^^^^^^^^^^^^^^^^^^^^^^^^^^^^^^^^^^^^^^^
RuntimeError: main thread is not in main loop
Exception ignored in: <module 'threading' from '/Library/Frameworks/Python.framework/Versions/3.11/lib/python3.11/threading.py'>
Traceback (most recent call last):
  File "/Library/Frameworks/Python.framework/Versions/3.11/lib/python3.11/threading.py", line 1583, in _shutdown
    lock.acquire()
TypeError: RFSwarmGUI.on_closing() takes from 1 to 2 positional arguments but 3 were given
